Failure # 1 (occurred at 2020-04-22_17-16-54)
Traceback (most recent call last):
  File "/home/ubuntu/anaconda3/envs/tensorflow_p36/lib/python3.6/site-packages/ray/tune/trial_runner.py", line 467, in _process_trial
    result = self.trial_executor.fetch_result(trial)
  File "/home/ubuntu/anaconda3/envs/tensorflow_p36/lib/python3.6/site-packages/ray/tune/ray_trial_executor.py", line 431, in fetch_result
    result = ray.get(trial_future[0], DEFAULT_GET_TIMEOUT)
  File "/home/ubuntu/anaconda3/envs/tensorflow_p36/lib/python3.6/site-packages/ray/worker.py", line 1504, in get
    raise value.as_instanceof_cause()
ray.exceptions.RayTaskError: [36mray::ESTrainer.train()[39m (pid=90540, ip=172.31.19.219)
  File "python/ray/_raylet.pyx", line 421, in ray._raylet.execute_task
  File "python/ray/_raylet.pyx", line 456, in ray._raylet.execute_task
  File "python/ray/_raylet.pyx", line 457, in ray._raylet.execute_task
  File "python/ray/_raylet.pyx", line 459, in ray._raylet.execute_task
  File "python/ray/_raylet.pyx", line 414, in ray._raylet.execute_task.function_executor
  File "/home/ubuntu/anaconda3/envs/tensorflow_p36/lib/python3.6/site-packages/ray/rllib/agents/trainer.py", line 448, in __init__
    super().__init__(config, logger_creator)
  File "/home/ubuntu/anaconda3/envs/tensorflow_p36/lib/python3.6/site-packages/ray/tune/trainable.py", line 174, in __init__
    self._setup(copy.deepcopy(self.config))
  File "/home/ubuntu/anaconda3/envs/tensorflow_p36/lib/python3.6/site-packages/ray/rllib/agents/trainer.py", line 591, in _setup
    self._init(self.config, self.env_creator)
  File "/home/ubuntu/anaconda3/envs/tensorflow_p36/lib/python3.6/site-packages/ray/rllib/agents/es/es.py", line 182, in _init
    env = env_creator(env_context)
  File "/home/ubuntu/anaconda3/envs/tensorflow_p36/lib/python3.6/site-packages/ray/rllib/agents/trainer.py", line 546, in <lambda>
    self.env_creator = lambda env_config: gym.make(env)
  File "/home/ubuntu/anaconda3/envs/tensorflow_p36/lib/python3.6/site-packages/gym/envs/registration.py", line 142, in make
    return registry.make(id, **kwargs)
  File "/home/ubuntu/anaconda3/envs/tensorflow_p36/lib/python3.6/site-packages/gym/envs/registration.py", line 87, in make
    env = spec.make(**kwargs)
  File "/home/ubuntu/anaconda3/envs/tensorflow_p36/lib/python3.6/site-packages/gym/envs/registration.py", line 58, in make
    cls = load(self.entry_point)
  File "/home/ubuntu/anaconda3/envs/tensorflow_p36/lib/python3.6/site-packages/gym/envs/registration.py", line 17, in load
    mod = importlib.import_module(mod_name)
  File "/home/ubuntu/anaconda3/envs/tensorflow_p36/lib/python3.6/importlib/__init__.py", line 126, in import_module
    return _bootstrap._gcd_import(name[level:], package, level)
  File "<frozen importlib._bootstrap>", line 994, in _gcd_import
  File "<frozen importlib._bootstrap>", line 971, in _find_and_load
  File "<frozen importlib._bootstrap>", line 955, in _find_and_load_unlocked
  File "<frozen importlib._bootstrap>", line 665, in _load_unlocked
  File "<frozen importlib._bootstrap_external>", line 678, in exec_module
  File "<frozen importlib._bootstrap>", line 219, in _call_with_frames_removed
  File "/home/ubuntu/anaconda3/envs/tensorflow_p36/lib/python3.6/site-packages/gym/envs/mujoco/__init__.py", line 1, in <module>
    from gym.envs.mujoco.mujoco_env import MujocoEnv
  File "/home/ubuntu/anaconda3/envs/tensorflow_p36/lib/python3.6/site-packages/gym/envs/mujoco/mujoco_env.py", line 12, in <module>
    import mujoco_py
  File "/home/ubuntu/anaconda3/envs/tensorflow_p36/lib/python3.6/site-packages/mujoco_py/__init__.py", line 3, in <module>
    from mujoco_py.builder import cymj, ignore_mujoco_warnings, functions, MujocoException
  File "/home/ubuntu/anaconda3/envs/tensorflow_p36/lib/python3.6/site-packages/mujoco_py/builder.py", line 510, in <module>
    cymj = load_cython_ext(mujoco_path)
  File "/home/ubuntu/anaconda3/envs/tensorflow_p36/lib/python3.6/site-packages/mujoco_py/builder.py", line 69, in load_cython_ext
    _ensure_set_env_var("LD_LIBRARY_PATH", lib_path)
  File "/home/ubuntu/anaconda3/envs/tensorflow_p36/lib/python3.6/site-packages/mujoco_py/builder.py", line 119, in _ensure_set_env_var
    var_name, var_name, lib_path))
Exception: 
Missing path to your environment variable. 
Current values LD_LIBRARY_PATH=/usr/lib64/openmpi/lib/:/usr/local/cuda/lib64:/usr/local/lib:/usr/lib:/usr/local/cuda/extras/CUPTI/lib64:/usr/local/mpi/lib:/lib/:/home/ubuntu/src/cntk/bindings/python/cntk/libs:/usr/local/cuda/lib64:/usr/local/lib:/usr/lib:/usr/local/cuda/extras/CUPTI/lib64:/usr/local/cuda/efa/lib:/usr/local/cuda/lib:/opt/amazon/efa/lib:/usr/local/mpi/lib:/usr/lib64/openmpi/lib/:/usr/local/cuda/lib64:/usr/local/lib:/usr/lib:/usr/local/cuda/extras/CUPTI/lib64:/usr/local/mpi/lib:/lib/:/home/ubuntu/src/cntk/bindings/python/cntk/libs:/usr/local/cuda/lib64:/usr/local/lib:/usr/lib:/usr/local/cuda/extras/CUPTI/lib64:/usr/local/cuda/efa/lib:/usr/local/cuda/lib:/opt/amazon/efa/lib:/usr/local/mpi/lib:/usr/lib64/openmpi/lib/:/usr/local/cuda/lib64:/usr/local/lib:/usr/lib:/usr/local/cuda/extras/CUPTI/lib64:/usr/local/mpi/lib:/lib/:/home/ubuntu/src/cntk/bindings/python/cntk/libs:/usr/local/cuda/lib64:/usr/local/lib:/usr/lib:/usr/local/cuda/extras/CUPTI/lib64:/usr/local/cuda/efa/lib:/usr/local/cuda/lib:/opt/amazon/efa/lib:/usr/local/mpi/lib:/usr/lib64/openmpi/lib/:/usr/local/cuda/lib64:/usr/local/lib:/usr/lib:/usr/local/cuda/extras/CUPTI/lib64:/usr/local/mpi/lib:/lib/:/usr/lib64/openmpi/lib/:/usr/local/cuda/lib64:/usr/local/lib:/usr/lib:/usr/local/cuda/extras/CUPTI/lib64:/usr/local/mpi/lib:/lib/:/home/ubuntu/src/cntk/bindings/python/cntk/libs:/usr/local/cuda/lib64:/usr/local/lib:/usr/lib:/usr/local/cuda/extras/CUPTI/lib64:/usr/local/cuda/efa/lib:/usr/local/cuda/lib:/opt/amazon/efa/lib:/usr/local/mpi/lib:
Please add following line to .bashrc:
export LD_LIBRARY_PATH=$LD_LIBRARY_PATH:/home/ubuntu/.mujoco/mujoco200/bin

